Workbook

Sheet PinMap
A1: GPIO号 | B1: 复用功能 | C1: Mux Selection | D1: 本项目功能 | E1: PCB 网络名 | F1: 是否使用 | G1: Comment（备注） | H1: 管脚组 | I1: 封装标号 | J1: 序号
A2: GPIO152 | C2: =IFERROR( INDEX(Sheet1!$B$1:$N$1, MATCH(B2, INDEX(Sheet1!$B$2:$N$170, MATCH($A2,Sheet1!$A$2:$A$170,0), 0 ), 0 ) ), "" ) | D2: GPIO | E2: DSP_PWM1_~{FAULT} | F2: =IF(E2<>"","Yes","No") -> Yes | J2: =IFERROR(VALUE(SUBSTITUTE(SUBSTITUTE(A2,"GPIO",""),"号","")),"") -> 152
A3: GPIO40 | C3: =IFERROR( INDEX(Sheet1!$B$1:$N$1, MATCH(B3, INDEX(Sheet1!$B$2:$N$170, MATCH($A3,Sheet1!$A$2:$A$170,0), 0 ), 0 ) ), "" ) | D3: GPIO | E3: DSP_PWM1~{_ENABLE} | F3: =IF(E3<>"","Yes","No") -> Yes | J3: =IFERROR(VALUE(SUBSTITUTE(SUBSTITUTE(A3,"GPIO",""),"号","")),"") -> 40
A4: GPIO109 | C4: =IFERROR( INDEX(Sheet1!$B$1:$N$1, MATCH(B4, INDEX(Sheet1!$B$2:$N$170, MATCH($A4,Sheet1!$A$2:$A$170,0), 0 ), 0 ) ), "" ) | D4: GPIO | E4: DSP_PWM2_~{FAULT} | F4: =IF(E4<>"","Yes","No") -> Yes | J4: =IFERROR(VALUE(SUBSTITUTE(SUBSTITUTE(A4,"GPIO",""),"号","")),"") -> 109
A5: GPIO108 | C5: =IFERROR( INDEX(Sheet1!$B$1:$N$1, MATCH(B5, INDEX(Sheet1!$B$2:$N$170, MATCH($A5,Sheet1!$A$2:$A$170,0), 0 ), 0 ) ), "" ) | D5: GPIO | E5: DSP_PWM2~{_ENABLE} | F5: =IF(E5<>"","Yes","No") -> Yes | J5: =IFERROR(VALUE(SUBSTITUTE(SUBSTITUTE(A5,"GPIO",""),"号","")),"") -> 108
A6: GPIO125 | C6: =IFERROR( INDEX(Sheet1!$B$1:$N$1, MATCH(B6, INDEX(Sheet1!$B$2:$N$170, MATCH($A6,Sheet1!$A$2:$A$170,0), 0 ), 0 ) ), "" ) | D6: GPIO | E6: DSP_PWM3_~{FAULT} | F6: =IF(E6<>"","Yes","No") -> Yes | J6: =IFERROR(VALUE(SUBSTITUTE(SUBSTITUTE(A6,"GPIO",""),"号","")),"") -> 125
A7: GPIO95 | C7: =IFERROR( INDEX(Sheet1!$B$1:$N$1, MATCH(B7, INDEX(Sheet1!$B$2:$N$170, MATCH($A7,Sheet1!$A$2:$A$170,0), 0 ), 0 ) ), "" ) | D7: GPIO | E7: DSP_PWM3~{_ENABLE} | F7: =IF(E7<>"","Yes","No") -> Yes | J7: =IFERROR(VALUE(SUBSTITUTE(SUBSTITUTE(A7,"GPIO",""),"号","")),"") -> 95
A8: GPIO117 | C8: =IFERROR( INDEX(Sheet1!$B$1:$N$1, MATCH(B8, INDEX(Sheet1!$B$2:$N$170, MATCH($A8,Sheet1!$A$2:$A$170,0), 0 ), 0 ) ), "" ) | D8: GPIO | E8: DSP_PWM4_~{FAULT} | F8: =IF(E8<>"","Yes","No") -> Yes | J8: =IFERROR(VALUE(SUBSTITUTE(SUBSTITUTE(A8,"GPIO",""),"号","")),"") -> 117
A9: GPIO28 | C9: =IFERROR( INDEX(Sheet1!$B$1:$N$1, MATCH(B9, INDEX(Sheet1!$B$2:$N$170, MATCH($A9,Sheet1!$A$2:$A$170,0), 0 ), 0 ) ), "" ) | D9: GPIO | E9: DSP_PWM4~{_ENABLE} | F9: =IF(E9<>"","Yes","No") -> Yes | J9: =IFERROR(VALUE(SUBSTITUTE(SUBSTITUTE(A9,"GPIO",""),"号","")),"") -> 28
A10: GPIO18 | B10: EPWM10A | C10: =IFERROR( INDEX(Sheet1!$B$1:$N$1, MATCH(B10, INDEX(Sheet1!$B$2:$N$170, MATCH($A10,Sheet1!$A$2:$A$170,0), 0 ), 0 ) ), "" ) -> 5 | D10: PWM | E10: DSP-PWM10A | F10: =IF(E10<>"","Yes","No") -> Yes | J10: =IFERROR(VALUE(SUBSTITUTE(SUBSTITUTE(A10,"GPIO",""),"号","")),"") -> 18
A11: GPIO19 | B11: EPWM10B | C11: =IFERROR( INDEX(Sheet1!$B$1:$N$1, MATCH(B11, INDEX(Sheet1!$B$2:$N$170, MATCH($A11,Sheet1!$A$2:$A$170,0), 0 ), 0 ) ), "" ) -> 5 | D11: PWM | E11: DSP-PWM10B | F11: =IF(E11<>"","Yes","No") -> Yes | J11: =IFERROR(VALUE(SUBSTITUTE(SUBSTITUTE(A11,"GPIO",""),"号","")),"") -> 19
A12: GPIO20 | B12: EPWM11A | C12: =IFERROR( INDEX(Sheet1!$B$1:$N$1, MATCH(B12, INDEX(Sheet1!$B$2:$N$170, MATCH($A12,Sheet1!$A$2:$A$170,0), 0 ), 0 ) ), "" ) -> 5 | D12: PWM | E12: DSP-PWM11A | F12: =IF(E12<>"","Yes","No") -> Yes | J12: =IFERROR(VALUE(SUBSTITUTE(SUBSTITUTE(A12,"GPIO",""),"号","")),"") -> 20
A13: GPIO21 | B13: EPWM11B | C13: =IFERROR( INDEX(Sheet1!$B$1:$N$1, MATCH(B13, INDEX(Sheet1!$B$2:$N$170, MATCH($A13,Sheet1!$A$2:$A$170,0), 0 ), 0 ) ), "" ) -> 5 | D13: PWM | E13: DSP-PWM11B | F13: =IF(E13<>"","Yes","No") -> Yes | J13: =IFERROR(VALUE(SUBSTITUTE(SUBSTITUTE(A13,"GPIO",""),"号","")),"") -> 21
A14: GPIO22 | B14: EPWM12A | C14: =IFERROR( INDEX(Sheet1!$B$1:$N$1, MATCH(B14, INDEX(Sheet1!$B$2:$N$170, MATCH($A14,Sheet1!$A$2:$A$170,0), 0 ), 0 ) ), "" ) -> 5 | D14: PWM | E14: DSP-PWM12A | F14: =IF(E14<>"","Yes","No") -> Yes | J14: =IFERROR(VALUE(SUBSTITUTE(SUBSTITUTE(A14,"GPIO",""),"号","")),"") -> 22
A15: GPIO23 | B15: EPWM12B | C15: =IFERROR( INDEX(Sheet1!$B$1:$N$1, MATCH(B15, INDEX(Sheet1!$B$2:$N$170, MATCH($A15,Sheet1!$A$2:$A$170,0), 0 ), 0 ) ), "" ) -> 5 | D15: PWM | E15: DSP-PWM12B | F15: =IF(E15<>"","Yes","No") -> Yes | J15: =IFERROR(VALUE(SUBSTITUTE(SUBSTITUTE(A15,"GPIO",""),"号","")),"") -> 23
A16: GPIO0 | B16: EPWM1A | C16: =IFERROR( INDEX(Sheet1!$B$1:$N$1, MATCH(B16, INDEX(Sheet1!$B$2:$N$170, MATCH($A16,Sheet1!$A$2:$A$170,0), 0 ), 0 ) ), "" ) -> 1 | D16: PWM | E16: DSP-PWM1A | F16: =IF(E16<>"","Yes","No") -> Yes | J16: =IFERROR(VALUE(SUBSTITUTE(SUBSTITUTE(A16,"GPIO",""),"号","")),"") -> 0
A17: GPIO1 | B17: EPWM1B | C17: =IFERROR( INDEX(Sheet1!$B$1:$N$1, MATCH(B17, INDEX(Sheet1!$B$2:$N$170, MATCH($A17,Sheet1!$A$2:$A$170,0), 0 ), 0 ) ), "" ) -> 1 | D17: PWM | E17: DSP-PWM1B | F17: =IF(E17<>"","Yes","No") -> Yes | J17: =IFERROR(VALUE(SUBSTITUTE(SUBSTITUTE(A17,"GPIO",""),"号","")),"") -> 1
A18: GPIO2 | B18: EPWM2A | C18: =IFERROR( INDEX(Sheet1!$B$1:$N$1, MATCH(B18, INDEX(Sheet1!$B$2:$N$170, MATCH($A18,Sheet1!$A$2:$A$170,0), 0 ), 0 ) ), "" ) -> 1 | D18: PWM | E18: DSP-PWM2A | F18: =IF(E18<>"","Yes","No") -> Yes | J18: =IFERROR(VALUE(SUBSTITUTE(SUBSTITUTE(A18,"GPIO",""),"号","")),"") -> 2
A19: GPIO3 | B19: EPWM2B | C19: =IFERROR( INDEX(Sheet1!$B$1:$N$1, MATCH(B19, INDEX(Sheet1!$B$2:$N$170, MATCH($A19,Sheet1!$A$2:$A$170,0), 0 ), 0 ) ), "" ) -> 1 | D19: PWM | E19: DSP-PWM2B | F19: =IF(E19<>"","Yes","No") -> Yes | J19: =IFERROR(VALUE(SUBSTITUTE(SUBSTITUTE(A19,"GPIO",""),"号","")),"") -> 3
A20: GPIO4 | B20: EPWM3A | C20: =IFERROR( INDEX(Sheet1!$B$1:$N$1, MATCH(B20, INDEX(Sheet1!$B$2:$N$170, MATCH($A20,Sheet1!$A$2:$A$170,0), 0 ), 0 ) ), "" ) -> 1 | D20: PWM | E20: DSP-PWM3A | F20: =IF(E20<>"","Yes","No") -> Yes | J20: =IFERROR(VALUE(SUBSTITUTE(SUBSTITUTE(A20,"GPIO",""),"号","")),"") -> 4
A21: GPIO5 | B21: EPWM3B | C21: =IFERROR( INDEX(Sheet1!$B$1:$N$1, MATCH(B21, INDEX(Sheet1!$B$2:$N$170, MATCH($A21,Sheet1!$A$2:$A$170,0), 0 ), 0 ) ), "" ) -> 1 | D21: PWM | E21: DSP-PWM3B | F21: =IF(E21<>"","Yes","No") -> Yes | J21: =IFERROR(VALUE(SUBSTITUTE(SUBSTITUTE(A21,"GPIO",""),"号","")),"") -> 5
... A30: GPIO10 | B30: EPWM6A | C30: =IFERROR( INDEX(Sheet1!$B$1:$N$1, MATCH(B30, INDEX(Sheet1!$B$2:$N$170, MATCH($A30,Sheet1!$A$2:$A$170,0), 0 ), 0 ) ), "" ) -> 1 | D30: PWM | E30: DSP-PWM6A | F30: =IF(E30<>"","Yes","No") -> Yes | J30: =IFERROR(VALUE(SUBSTITUTE(SUBSTITUTE(A30,"GPIO",""),"号","")),"") -> 10
A31: GPIO29 | C31: =IFERROR( INDEX(Sheet1!$B$1:$N$1, MATCH(B31, INDEX(Sheet1!$B$2:$N$170, MATCH($A31,Sheet1!$A$2:$A$170,0), 0 ), 0 ) ), "" ) | D31: CAN | E31: DSP_A_CAN_EN | F31: =IF(E31<>"","Yes","No") -> Yes | J31: =IFERROR(VALUE(SUBSTITUTE(SUBSTITUTE(A31,"GPIO",""),"号","")),"") -> 29
A32: GPIO30 | B32: CANA_RX | C32: =IFERROR( INDEX(Sheet1!$B$1:$N$1, MATCH(B32, INDEX(Sheet1!$B$2:$N$170, MATCH($A32,Sheet1!$A$2:$A$170,0), 0 ), 0 ) ), "" ) -> 1 | D32: CAN | E32: DSP_A_CAN_RX | F32: =IF(E32<>"","Yes","No") -> Yes | J32: =IFERROR(VALUE(SUBSTITUTE(SUBSTITUTE(A32,"GPIO",""),"号","")),"") -> 30
A33: GPIO31 | B33: CANA_TX | C33: =IFERROR( INDEX(Sheet1!$B$1:$N$1, MATCH(B33, INDEX(Sheet1!$B$2:$N$170, MATCH($A33,Sheet1!$A$2:$A$170,0), 0 ), 0 ) ), "" ) -> 1 | D33: CAN | E33: DSP_A_CAN_TX | F33: =IF(E33<>"","Yes","No") -> Yes | J33: =IFERROR(VALUE(SUBSTITUTE(SUBSTITUTE(A33,"GPIO",""),"号","")),"") -> 31
A34: GPIO32 | B34: I2CA_SDA | C34: =IFERROR( INDEX(Sheet1!$B$1:$N$1, MATCH(B34, INDEX(Sheet1!$B$2:$N$170, MATCH($A34,Sheet1!$A$2:$A$170,0), 0 ), 0 ) ), "" ) -> 1 | D34: I2C | E34: MSDAA | F34: =IF(E34<>"","Yes","No") -> Yes | J34: =IFERROR(VALUE(SUBSTITUTE(SUBSTITUTE(A34,"GPIO",""),"号","")),"") -> 32
A35: GPIO33 | B35: I2CA_SCL | C35: =IFERROR( INDEX(Sheet1!$B$1:$N$1, MATCH(B35, INDEX(Sheet1!$B$2:$N$170, MATCH($A35,Sheet1!$A$2:$A$170,0), 0 ), 0 ) ), "" ) -> 1 | D35: I2C | E35: MSCLA | F35: =IF(E35<>"","Yes","No") -> Yes | J35: =IFERROR(VALUE(SUBSTITUTE(SUBSTITUTE(A35,"GPIO",""),"号","")),"") -> 33
A36: GPIO34 | B36: I2CB_SDA | C36: =IFERROR( INDEX(Sheet1!$B$1:$N$1, MATCH(B36, INDEX(Sheet1!$B$2:$N$170, MATCH($A36,Sheet1!$A$2:$A$170,0), 0 ), 0 ) ), "" ) -> 6 | D36: I2C | E36: MSCLB | F36: =IF(E36<>"","Yes","No") -> Yes | J36: =IFERROR(VALUE(SUBSTITUTE(SUBSTITUTE(A36,"GPIO",""),"号","")),"") -> 34
A37: GPIO35 | B37: I2CB_SCL | C37: =IFERROR( INDEX(Sheet1!$B$1:$N$1, MATCH(B37, INDEX(Sheet1!$B$2:$N$170, MATCH($A37,Sheet1!$A$2:$A$170,0), 0 ), 0 ) ), "" ) -> 6 | D37: I2C | E37: MSDAB | F37: =IF(E37<>"","Yes","No") -> Yes | J37: =IFERROR(VALUE(SUBSTITUTE(SUBSTITUTE(A37,"GPIO",""),"号","")),"") -> 35
A38: GPIO36 | F38: =IF(E38<>"","Yes","No") -> No | J38: =IFERROR(VALUE(SUBSTITUTE(SUBSTITUTE(A38,"GPIO",""),"号","")),"") -> 36
A39: GPIO37 | C39: =IFERROR( INDEX(Sheet1!$B$1:$N$1, MATCH(B39, INDEX(Sheet1!$B$2:$N$170, MATCH($A39,Sheet1!$A$2:$A$170,0), 0 ), 0 ) ), "" ) | D39: CAN | E39: DSP_B_CAN_EN | F39: =IF(E39<>"","Yes","No") -> Yes | J39: =IFERROR(VALUE(SUBSTITUTE(SUBSTITUTE(A39,"GPIO",""),"号","")),"") -> 37
A40: GPIO38 | B40: CANB_TX | C40: =IFERROR( INDEX(Sheet1!$B$1:$N$1, MATCH(B40, INDEX(Sheet1!$B$2:$N$170, MATCH($A40,Sheet1!$A$2:$A$170,0), 0 ), 0 ) ), "" ) -> 6 | D40: CAN | E40: DSP_B_CAN_TX | F40: =IF(E40<>"","Yes","No") -> Yes | J40: =IFERROR(VALUE(SUBSTITUTE(SUBSTITUTE(A40,"GPIO",""),"号","")),"") -> 38
A41: GPIO39 | B41: CANB_RX | C41: =IFERROR( INDEX(Sheet1!$B$1:$N$1, MATCH(B41, INDEX(Sheet1!$B$2:$N$170, MATCH($A41,Sheet1!$A$2:$A$170,0), 0 ), 0 ) ), "" ) -> 6 | D41: CAN | E41: DSP_B_CAN_RX | F41: =IF(E41<>"","Yes","No") -> Yes | J41: =IFERROR(VALUE(SUBSTITUTE(SUBSTITUTE(A41,"GPIO",""),"号","")),"") -> 39
A42: GPIO11 | B42: EPWM6B | C42: =IFERROR( INDEX(Sheet1!$B$1:$N$1, MATCH(B42, INDEX(Sheet1!$B$2:$N$170, MATCH($A42,Sheet1!$A$2:$A$170,0), 0 ), 0 ) ), "" ) -> 1 | D42: PWM | E42: DSP-PWM6B | F42: =IF(E42<>"","Yes","No") -> Yes | J42: =IFERROR(VALUE(SUBSTITUTE(SUBSTITUTE(A42,"GPIO",""),"号","")),"") -> 11
A43: GPIO41 | C43: =IFERROR( INDEX(Sheet1!$B$1:$N$1, MATCH(B43, INDEX(Sheet1!$B$2:$N$170, MATCH($A43,Sheet1!$A$2:$A$170,0), 0 ), 0 ) ), "" ) | D43: GPIO | E43: DI-2-DSP-3.3V | F43: =IF(E43<>"","Yes","No") -> Yes | J43: =IFERROR(VALUE(SUBSTITUTE(SUBSTITUTE(A43,"GPIO",""),"号","")),"") -> 41
A44: GPIO42 | C44: =IFERROR( INDEX(Sheet1!$B$1:$N$1, MATCH(B44, INDEX(Sheet1!$B$2:$N$170, MATCH($A44,Sheet1!$A$2:$A$170,0), 0 ), 0 ) ), "" ) | D44: Hall | E44: HALL2_W | F44: =IF(E44<>"","Yes","No") -> Yes | J44: =IFERROR(VALUE(SUBSTITUTE(SUBSTITUTE(A44,"GPIO",""),"号","")),"") -> 42
A45: GPIO43 | C45: =IFERROR( INDEX(Sheet1!$B$1:$N$1, MATCH(B45, INDEX(Sheet1!$B$2:$N$170, MATCH($A45,Sheet1!$A$2:$A$170,0), 0 ), 0 ) ), "" ) | F45: =IF(E45<>"","Yes","No") -> No | J45: =IFERROR(VALUE(SUBSTITUTE(SUBSTITUTE(A45,"GPIO",""),"号","")),"") -> 43
A46: GPIO44 | B46: ESC_TX1_CLK | C46: =IFERROR( INDEX(Sheet1!$B$1:$N$1, MATCH(B46, INDEX(Sheet1!$B$2:$N$170, MATCH($A46,Sheet1!$A$2:$A$170,0), 0 ), 0 ) ), "" ) -> 14 | D46: EtherCAT | E46: ESC_TX1_CLK | F46: =IF(E46<>"","Yes","No") -> Yes | G46: 核心板 | J46: =IFERROR(VALUE(SUBSTITUTE(SUBSTITUTE(A46,"GPIO",""),"号","")),"") -> 44
A47: GPIO45 | B47: ESC_TX1_ENA | C47: =IFERROR( INDEX(Sheet1!$B$1:$N$1, MATCH(B47, INDEX(Sheet1!$B$2:$N$170, MATCH($A47,Sheet1!$A$2:$A$170,0), 0 ), 0 ) ), "" ) -> 14 | D47: EtherCAT | E47: ESC_TX1_EN | F47: =IF(E47<>"","Yes","No") -> Yes | G47: 核心板 | J47: =IFERROR(VALUE(SUBSTITUTE(SUBSTITUTE(A47,"GPIO",""),"号","")),"") -> 45
A48: GPIO46 | B48: ESC_MDIO_CLK | C48: =IFERROR( INDEX(Sheet1!$B$1:$N$1, MATCH(B48, INDEX(Sheet1!$B$2:$N$170, MATCH($A48,Sheet1!$A$2:$A$170,0), 0 ), 0 ) ), "" ) -> 14 | D48: EtherCAT | E48: ESC_MDC | F48: =IF(E48<>"","Yes","No") -> Yes | G48: 核心板 | J48: =IFERROR(VALUE(SUBSTITUTE(SUBSTITUTE(A48,"GPIO",""),"号","")),"") -> 46
...

Sheet Lists
A1: PeripheralType | B1: Direction | C1: IOType | D1: Pull | E1: InitialState | F1: UsedFlag | G1: SafetyLevel | I1: 说明 / Notes
A2: GPIO | B2: Input | C2: Digital | D2: None | E2: Low | F2: Yes | G2: Normal | I2: 此工作簿为 TMS320F28377D PTP-176 封装 PinMap 模板。PinMap 页第 2~177 行已预填封装引脚号 1~176，其它信息请参考 TI Datasheet Table 5-1 手工补充 MCU 引脚名等。
A3: ADC | B3: Output | C3: Analog | D3: Pull-up | E3: High | F3: No | G3: Critical
A4: PWM | B4: Bidirectional | C4: Power | D4: Pull-down | E4: Hi-Z | G4: Safety-related
A5: eQEP | B5: Analog Input | C5: Ground | D5: External | E5: Don't care | G5: Debug only
A6: UNUSED | B6: Analog Output | C6: Clock
A7: SPI | C7: Test/JTAG
A8: I2C
A9: SCI
A10: CAN
A11: EtherCAT
A12: Hall
A13: XCLKIN
A14: CLB
A15: LED
A16: SDFM
A17: Other

Sheet Sheet1
A1: GPIO (0,4,8,12) | B1: 1 | C1: 2 | D1: 3 | E1: 5 | F1: 6 | G1: 7 | H1: 9 | I1: 10 | J1: 11 | K1: 13 | L1: 14 | M1: 15 | N1: ALT
A2: GPIO0 | B2: EPWM1A | F2: I2CA_SDA | H2: CM-I2CA_SDA | I2: ESC_GPI0 | K2: FSITXA_D0
A3: GPIO1 | B3: EPWM1B | D3: MFSRB | F3: I2CA_SCL | H3: CM-I2CA_SCL | I3: ESC_GPI1 | K3: FSITXA_D1
A4: GPIO2 | B4: EPWM2A | E4: OUTPUTXBAR1 | F4: I2CB_SDA | I4: ESC_GPI2 | K4: FSITXA_CLK
A5: GPIO3 | B5: EPWM2B | C5: OUTPUTXBAR2 | D5: MCLKRB | E5: OUTPUTXBAR2 | F5: I2CB_SCL | I5: ESC_GPI3 | K5: FSIRXA_D0
A6: GPIO4 | B6: EPWM3A | E6: OUTPUTXBAR3 | F6: CANA_TX | H6: MCAN_TX | I6: ESC_GPI4 | K6: FSIRXA_D1
A7: GPIO5 | B7: EPWM3B | C7: MFSRA | D7: OUTPUTXBAR3 | F7: CANA_RX | H7: MCAN_RX | I7: ESC_GPI5 | K7: FSIRXA_CLK
A8: GPIO6 | B8: EPWM4A | C8: OUTPUTXBAR4 | D8: EXTSYNCOUT | E8: EQEP3_A | F8: CANB_TX | I8: ESC_GPI6 | K8: FSITXB_D0
A9: GPIO7 | B9: EPWM4B | C9: MCLKRA | D9: OUTPUTXBAR5 | E9: EQEP3_B | F9: CANB_RX | I9: ESC_GPI7 | K9: FSITXB_D1
A10: GPIO8 | B10: EPWM5A | C10: CANB_TX | D10: ADCSOCAO | E10: EQEP3_STROBE | F10: SCIA_TX | H10: MCAN_TX | I10: ESC_GPO0 | K10: FSITXB_CLK | L10: FSITXA_D1 | M10: FSIRXA_D0
A11: GPIO9 | B11: EPWM5B | C11: SCIB_TX | D11: OUTPUTXBAR6 | E11: EQEP3_INDEX | F11: SCIA_RX | I11: ESC_GPO1 | K11: FSIRXB_D0 | L11: FSITXA_D0 | M11: FSIRXA_CLK
A12: GPIO10 | B12: EPWM6A | C12: CANB_RX | D12: ADCSOCBO | E12: EQEP1_A | F12: SCIB_TX | H12: MCAN_RX | I12: ESC_GPO2 | K12: FSIRXB_D1 | L12: FSITXA_CLK | M12: FSIRXA_D1
A13: GPIO11 | B13: EPWM6B | C13: SCIB_RX | D13: OUTPUTXBAR7 | E13: EQEP1_B | F13: SCIB_RX | I13: ESC_GPO3 | K13: FSIRXB_CLK | L13: FSIRXA_D1
A14: GPIO12 | B14: EPWM7A | C14: CANB_TX | D14: MDXB | E14: EQEP1_STROBE | F14: SCIC_TX | I14: ESC_GPO4 | K14: FSIRXC_D0 | L14: FSIRXA_D0
A15: GPIO13 | B15: EPWM7B | C15: CANB_RX | D15: MDRB | E15: EQEP1_INDEX | F15: SCIC_RX | I15: ESC_GPO5 | K15: FSIRXC_D1 | L15: FSIRXA_CLK
A16: GPIO14 | B16: EPWM8A | C16: SCIB_TX | D16: MCLKXB | F16: OUTPUTXBAR3 | I16: ESC_GPO6 | K16: FSIRXC_CLK
A17: GPIO15 | B17: EPWM8B | C17: SCIB_RX | D17: MFSXB | F17: OUTPUTXBAR4 | I17: ESC_GPO7 | K17: FSIRXD_D0
A18: GPIO16 | B18: SPIA_SIMO | C18: CANB_TX | D18: OUTPUTXBAR7 | E18: EPWM9A | G18: SD1_D1 | J18: SSIA_TX | K18: FSIRXD_D1
A19: GPIO17 | B19: SPIA_SOMI | C19: CANB_RX | D19: OUTPUTXBAR8 | E19: EPWM9B | G19: SD1_C1 | J19: SSIA_RX | K19: FSIRXD_CLK
A20: GPIO18 | B20: SPIA_CLK | C20: SCIB_TX | D20: CANA_RX | E20: EPWM10A | G20: SD1_D2 | H20: MCAN_RX | I20: EMIF1_CS2n | J20: SSIA_CLK | K20: FSIRXE_D0
A21: GPIO19 | B21: SPIA_STEn | C21: SCIB_RX | D21: CANA_TX | E21: EPWM10B | G21: SD1_C2 | H21: MCAN_TX | I21: EMIF1_CS3n | J21: SSIA_FSS | K21: FSIRXE_D1
A22: GPIO20 | B22: EQEP1_A | C22: MDXA | D22: CANB_TX | E22: EPWM11A | G22: SD1_D3 | I22: EMIF1_BA0 | J22: TRACE_DATA0 | K22: FSIRXE_CLK | L22: SPIC_SIMO
A23: GPIO21 | B23: EQEP1_B | C23: MDRA | D23: CANB_RX | E23: EPWM11B | G23: SD1_C3 | I23: EMIF1_BA1 | J23: TRACE_DATA1 | K23: FSIRXF_D0 | L23: SPIC_SOMI
A24: GPIO22 | B24: EQEP1_STROBE | C24: MCLKXA | D24: SCIB_TX | E24: EPWM12A | F24: SPIB_CLK | G24: SD1_D4 | H24: MCAN_TX | I24: EMIF1_RAS | J24: TRACE_DATA2 | K24: FSIRXF_D1 | L24: SPIC_CLK
A25: GPIO23 | B25: EQEP1_INDEX | C25: MFSXA | D25: SCIB_RX | E25: EPWM12B | F25: SPIB_STEn | G25: SD1_C4 | H25: MCAN_RX | I25: EMIF1_CAS | J25: TRACE_DATA3 | K25: FSIRXF_CLK | L25: SPIC_STEn
A26: GPIO24 | B26: OUTPUTXBAR1 | C26: EQEP2_A | D26: MDXB | F26: SPIB_SIMO | G26: SD2_D1 | H26: PMBUSA_SCL | I26: EMIF1_DQM0 | J26: TRACE_CLK | K26: EPWM13A | M26: FSIRXG_D0
A27: GPIO25 | B27: OUTPUTXBAR2 | C27: EQEP2_B | D27: MDRB | F27: SPIB_SOMI | G27: SD2_C1 | H27: PMBUSA_SDA | I27: EMIF1_DQM1 | J27: TRACE_SWO | K27: EPWM13B | L27: FSITXA_D1 | M27: FSIRXG_D1
A28: GPIO26 | B28: OUTPUTXBAR3 | C28: EQEP2_INDEX | D28: MCLKXB | E28: OUTPUTXBAR3 | F28: SPIB_CLK | G28: SD2_D2 | H28: PMBUSA_ALERT | I28: EMIF1_DQM2 | J28: ESC_MDIO_CLK | K28: EPWM14A | L28: FSITXA_D0 | M28: FSIRXG_CLK
A29: GPIO27 | B29: OUTPUTXBAR4 | C29: EQEP2_STROBE | D29: MFSXB | E29: OUTPUTXBAR4 | F29: SPIB_STEn | G29: SD2_C2 | H29: PMBUSA_CTL | I29: EMIF1_DQM3 | J29: ESC_MDIO_DATA | K29: EPWM14B | L29: FSITXA_CLK | M29: FSIRXH_D0
A30: GPIO28 | B30: SCIA_RX | C30: EMIF1_CS4n | E30: OUTPUTXBAR5 | F30: EQEP3_A | G30: SD2_D3 | H30: EMIF1_CS2n | K30: EPWM15A | M30: FSIRXH_D1
A31: GPIO29 | B31: SCIA_TX | C31: EMIF1_SDCKE | E31: OUTPUTXBAR6 | F31: EQEP3_B | G31: SD2_C3 | H31: EMIF1_CS3n | I31: ESC_LATCH0 | J31: ESC_I2C_SDA | K31: EPWM15B | L31: ESC_SYNC0 | M31: FSIRXH_CLK
A32: GPIO30 | B32: CANA_RX | C32: EMIF1_CLK | D32: MCAN_RX | E32: OUTPUTXBAR7 | F32: EQEP3_STROBE | G32: SD2_D4 | H32: EMIF1_CS4n | I32: ESC_LATCH1 | J32: ESC_I2C_SCL | K32: EPWM16A | L32: ESC_SYNC1 | M32: SPID_SIMO
A33: GPIO31 | B33: CANA_TX | C33: EMIF1_WEn | D33: MCAN_TX | E33: OUTPUTXBAR8 | F33: EQEP3_INDEX | G33: SD2_C4 | H33: EMIF1_RNW | I33: I2CA_SDA | J33: CM-I2CA_SDA | K33: EPWM16B | M33: SPID_SOMI
A34: GPIO32 | B34: I2CA_SDA | C34: EMIF1_CS0n | D34: SPIA_SIMO | G34: CLB_OUTPUTXBAR1 | H34: EMIF1_OEn | I34: I2CA_SCL | J34: CM-I2CA_SCL | M34: SPID_CLK
A35: GPIO33 | B35: I2CA_SCL | C35: EMIF1_RNW | D35: SPIA_SOMI | G35: CLB_OUTPUTXBAR2 | H35: EMIF1_BA0 | M35: SPID_STEn
A36: GPIO34 | B36: OUTPUTXBAR1 | C36: EMIF1_CS2n | D36: SPIA_CLK | F36: I2CB_SDA | G36: CLB_OUTPUTXBAR3 | H36: EMIF1_BA1 | I36: ESC_LATCH0 | J36: ENET_MII_CRS | K36: SCIA_TX | L36: ESC_SYNC0
A37: GPIO35 | B37: SCIA_RX | C37: EMIF1_CS3n | D37: SPIA_STEn | F37: I2CB_SCL | G37: CLB_OUTPUTXBAR4 | H37: EMIF1_A0 | I37: ESC_LATCH1 | J37: ENET_MII_COL | L37: ESC_SYNC1
A38: GPIO36 | B38: SCIA_TX | C38: EMIF1_WAIT | F38: CANA_RX | G38: CLB_OUTPUTXBAR5 | H38: EMIF1_A1 | I38: MCAN_RX | K38: SD1_D1
A39: GPIO37 | B39: OUTPUTXBAR2 | C39: EMIF1_OEn | F39: CANA_TX | G39: CLB_OUTPUTXBAR6 | H39: EMIF1_A2 | I39: MCAN_TX | K39: SD1_D2
A40: GPIO38 | C40: EMIF1_A0 | E40: SCIC_TX | F40: CANB_TX | G40: CLB_OUTPUTXBAR7 | H40: EMIF1_A3 | I40: ENET_MII_RX_DV | J40: ENET_MII_CRS | K40: SD1_D3
...
